Workbook

Sheet Read Me
B2: Executive Business Intelligence Ecosystem
B3: AED 10,000,000 Annual Business Value — Demonstration Model
B5: ABOUT THIS WORKBOOK
B6: This workbook is a full business intelligence ecosystem built around a single scenario: a business with
B7: AED 10,000,000 in total annual business value, split across four business units. It demonstrates the
B8: kind of end-to-end reporting infrastructure used in executive reporting, revenue operations, and financial
B9: administration — from raw data, to a data dictionary of assumptions, to a live executive dashboard.
B11: All monetary values are illustrative and clearly documented as assumptions or synthetic data for
B12: demonstration purposes. No formula recalculates a value that should instead be sourced from a real system.
B14: HOW THE WORKBOOK IS STRUCTURED
B15: 1. Assumptions
B16: The single source of truth. Every driver — revenue share, COGS %, credit terms, DSO and inventory turnover targets, monthly seasonality — lives here. Change a number here and it flows through the entire model.
... B33: To extend the model: add a new month or business unit row in 'Monthly Data', following the same formula pattern as the row above it, then the Tracker, Analysis and Dashboard tabs update automatically.

Sheet Assumptions
A1: Business Assumptions & Data Dictionary
A2: Single source of truth — every driver in this model traces back to a cell on this tab.
A4: COMPANY-LEVEL ASSUMPTIONS
A5: Total Annual Business Value (AED) | B5: 10000000
A6: Reporting Year | B6: 2026
A8: BUSINESS UNIT REVENUE SHARE
A9: Business Unit | B9: Revenue Share %
A10: Executive & Corporate Services | B10: 0.35
A11: Client Operations & Revenue Recovery | B11: 0.3
A12: Product & Technology (Atrium) | B12: 0.2
A13: Consulting & Advisory | B13: 0.15
A14: Total | B14: =SUM(B10:B13) -> 1
A17: BUSINESS UNIT OPERATING ASSUMPTIONS
A18: Business Unit | B18: COGS % | C18: Credit Sales % | D18: DSO Target (Days) | E18: Inventory Turnover Target (x)
A19: Executive & Corporate Services | B19: 0.55 | C19: 0.85 | D19: 45 | E19: 8
A20: Client Operations & Revenue Recovery | B20: 0.6 | C20: 0.9 | D20: 50 | E20: 6
A21: Product & Technology (Atrium) | B21: 0.4 | C21: 0.7 | D21: 30 | E21: 12
A22: Consulting & Advisory | B22: 0.5 | C22: 0.8 | D22: 40 | E22: 10
A25: MONTHLY SEASONALITY & CALENDAR
A26: Month | B26: Seasonality Index | C26: Days in Month
A27: Jan-2026 | B27: 0.9 | C27: 31
A28: Feb-2026 | B28: 0.88 | C28: 28
A29: Mar-2026 | B29: 0.95 | C29: 31
A30: Apr-2026 | B30: 0.92 | C30: 30
A31: May-2026 | B31: 0.9 | C31: 31
A32: Jun-2026 | B32: 0.8 | C32: 30
A33: Jul-2026 | B33: 0.75 | C33: 31
A34: Aug-2026 | B34: 0.8 | C34: 31
A35: Sep-2026 | B35: 1.05 | C35: 30
A36: Oct-2026 | B36: 1.15 | C36: 31
A37: Nov-2026 | B37: 1.25 | C37: 30
A38: Dec-2026 | B38: 1.35 | C38: 31
A39: Total | B39: =SUM(B27:B38) -> 11.7

Sheet Monthly Data
A1: Month | B1: Business Unit | C1: Revenue Target (AED) | D1: Revenue Actual (AED) | E1: Achievement % | F1: COGS % | G1: COGS (AED) | H1: Gross Profit (AED) | I1: Gross Margin % | J1: Credit Sales % | K1: Credit Sales (AED) | L1: Closing Receivables (AED) | M1: Days in Month | N1: DSO (Days) | O1: Average Inventory (AED) | P1: Inventory Turnover (x) | Q1: Inventory Days
A2: Jan-2026 | B2: Executive & Corporate Services | C2: =Assumptions!$B$5*Assumptions!$B$10*Assumptions!$B$27/Assumptions!$B$39 -> 269230.77 | D2: =C2*1.0279 -> 276742.31 | E2: =IFERROR(D2/C2,0) -> 1.0279 | F2: =Assumptions!$B$19 -> 0.55 | G2: =D2*F2 -> 152208.27 | H2: =D2-G2 -> 124534.04 | I2: =IFERROR(H2/D2,0) -> 0.45 | J2: =Assumptions!$C$19 -> 0.85 | K2: =D2*J2 -> 235230.96 | L2: =(Assumptions!$D$19/Assumptions!$C$27)*K2*0.8575 -> 292805.64 | M2: =Assumptions!$C$27 -> 31 | N2: =IFERROR((L2/K2)*M2,0) -> 38.5875 | O2: =IFERROR((G2*12)/Assumptions!$E$19*0.946,0) -> 215983.53 | P2: =IFERROR((G2*12)/O2,0) -> 8.4566596 | Q2: =IFERROR(365/P2,0) -> 43.16125
A3: Jan-2026 | B3: Client Operations & Revenue Recovery | C3: =Assumptions!$B$5*Assumptions!$B$11*Assumptions!$B$27/Assumptions!$B$39 -> 230769.23 | D3: =C3*0.9446 -> 217984.62 | E3: =IFERROR(D3/C3,0) -> 0.9446 | F3: =Assumptions!$B$20 -> 0.6 | G3: =D3*F3 -> 130790.77 | H3: =D3-G3 -> 87193.846 | I3: =IFERROR(H3/D3,0) -> 0.4 | J3: =Assumptions!$C$20 -> 0.9 | K3: =D3*J3 -> 196186.15 | L3: =(Assumptions!$D$20/Assumptions!$C$27)*K3*1.0709 -> 338864.12 | M3: =Assumptions!$C$27 -> 31 | N3: =IFERROR((L3/K3)*M3,0) -> 53.545 | O3: =IFERROR((G3*12)/Assumptions!$E$20*1.0424,0) -> 272672.6 | P3: =IFERROR((G3*12)/O3,0) -> 5.7559478 | Q3: =IFERROR(365/P3,0) -> 63.412667
A4: Jan-2026 | B4: Product & Technology (Atrium) | C4: =Assumptions!$B$5*Assumptions!$B$12*Assumptions!$B$27/Assumptions!$B$39 -> 153846.15 | D4: =C4*1.0784 -> 165907.69 | E4: =IFERROR(D4/C4,0) -> 1.0784 | F4: =Assumptions!$B$21 -> 0.4 | G4: =D4*F4 -> 66363.077 | H4: =D4-G4 -> 99544.615 | I4: =IFERROR(H4/D4,0) -> 0.6 | J4: =Assumptions!$C$21 -> 0.7 | K4: =D4*J4 -> 116135.38 | L4: =(Assumptions!$D$21/Assumptions!$C$27)*K4*0.8761 -> 98464.075 | M4: =Assumptions!$C$27 -> 31 | N4: =IFERROR((L4/K4)*M4,0) -> 26.283 | O4: =IFERROR((G4*12)/Assumptions!$E$21*0.9813,0) -> 65122.087 | P4: =IFERROR((G4*12)/O4,0) -> 12.228676 | Q4: =IFERROR(365/P4,0) -> 29.847875
A5: Jan-2026 | B5: Consulting & Advisory | C5: =Assumptions!$B$5*Assumptions!$B$13*Assumptions!$B$27/Assumptions!$B$39 -> 115384.62 | D5: =C5*0.906 -> 104538.46 | E5: =IFERROR(D5/C5,0) -> 0.906 | F5: =Assumptions!$B$22 -> 0.5 | G5: =D5*F5 -> 52269.231 | H5: =D5-G5 -> 52269.231 | I5: =IFERROR(H5/D5,0) -> 0.5 | J5: =Assumptions!$C$22 -> 0.8 | K5: =D5*J5 -> 83630.769 | L5: =(Assumptions!$D$22/Assumptions!$C$27)*K5*0.9156 -> 98803.009 | M5: =Assumptions!$C$27 -> 31 | N5: =IFERROR((L5/K5)*M5,0) -> 36.624 | O5: =IFERROR((G5*12)/Assumptions!$E$22*1.0013,0) -> 62804.617 | P5: =IFERROR((G5*12)/O5,0) -> 9.9870169 | Q5: =IFERROR(365/P5,0) -> 36.54745
A6: Feb-2026 | B6: Executive & Corporate Services | C6: =Assumptions!$B$5*Assumptions!$B$10*Assumptions!$B$28/Assumptions!$B$39 -> 263247.86 | D6: =C6*0.9041 -> 238002.39 | E6: =IFERROR(D6/C6,0) -> 0.9041 | F6: =Assumptions!$B$19 -> 0.55 | G6: =D6*F6 -> 130901.32 | H6: =D6-G6 -> 107101.08 | I6: =IFERROR(H6/D6,0) -> 0.45 | J6: =Assumptions!$C$19 -> 0.85 | K6: =D6*J6 -> 202302.03 | L6: =(Assumptions!$D$19/Assumptions!$C$28)*K6*0.9097 -> 295769.19 | M6: =Assumptions!$C$28 -> 28 | N6: =IFERROR((L6/K6)*M6,0) -> 40.9365 | O6: =IFERROR((G6*12)/Assumptions!$E$19*1.036,0) -> 203420.65 | P6: =IFERROR((G6*12)/O6,0) -> 7.7220077 | Q6: =IFERROR(365/P6,0) -> 47.2675
A7: Feb-2026 | B7: Client Operations & Revenue Recovery | C7: =Assumptions!$B$5*Assumptions!$B$11*Assumptions!$B$28/Assumptions!$B$39 -> 225641.03 | D7: =C7*1.0085 -> 227558.97 | E7: =IFERROR(D7/C7,0) -> 1.0085 | F7: =Assumptions!$B$20 -> 0.6 | G7: =D7*F7 -> 136535.38 | H7: =D7-G7 -> 91023.59 | I7: =IFERROR(H7/D7,0) -> 0.4 | J7: =Assumptions!$C$20 -> 0.9 | K7: =D7*J7 -> 204803.08 | L7: =(Assumptions!$D$20/Assumptions!$C$28)*K7*0.9161 -> 335035.89 | M7: =Assumptions!$C$28 -> 28 | N7: =IFERROR((L7/K7)*M7,0) -> 45.805 | O7: =IFERROR((G7*12)/Assumptions!$E$20*1.0214,0) -> 278914.48 | P7: =IFERROR((G7*12)/O7,0) -> 5.8742902 | Q7: =IFERROR(365/P7,0) -> 62.135167
A8: Feb-2026 | B8: Product & Technology (Atrium) | C8: =Assumptions!$B$5*Assumptions!$B$12*Assumptions!$B$28/Assumptions!$B$39 -> 150427.35 | D8: =C8*1.0624 -> 159814.02 | E8: =IFERROR(D8/C8,0) -> 1.0624 | F8: =Assumptions!$B$21 -> 0.4 | G8: =D8*F8 -> 63925.607 | H8: =D8-G8 -> 95888.41 | I8: =IFERROR(H8/D8,0) -> 0.6 | J8: =Assumptions!$C$21 -> 0.7 | K8: =D8*J8 -> 111869.81 | L8: =(Assumptions!$D$21/Assumptions!$C$28)*K8*0.8519 -> 102109.17 | M8: =Assumptions!$C$28 -> 28 | N8: =IFERROR((L8/K8)*M8,0) -> 25.557 | O8: =IFERROR((G8*12)/Assumptions!$E$21*1.0734,0) -> 68617.746 | P8: =IFERROR((G8*12)/O8,0) -> 11.17943 | Q8: =IFERROR(365/P8,0) -> 32.64925
A9: Feb-2026 | B9: Consulting & Advisory | C9: =Assumptions!$B$5*Assumptions!$B$13*Assumptions!$B$28/Assumptions!$B$39 -> 112820.51 | D9: =C9*1.041 -> 117446.15 | E9: =IFERROR(D9/C9,0) -> 1.041 | F9: =Assumptions!$B$22 -> 0.5 | G9: =D9*F9 -> 58723.077 | H9: =D9-G9 -> 58723.077 | I9: =IFERROR(H9/D9,0) -> 0.5 | J9: =Assumptions!$C$22 -> 0.8 | K9: =D9*J9 -> 93956.923 | L9: =(Assumptions!$D$22/Assumptions!$C$28)*K9*0.9521 -> 127794.84 | M9: =Assumptions!$C$28 -> 28 | N9: =IFERROR((L9/K9)*M9,0) -> 38.084 | O9: =IFERROR((G9*12)/Assumptions!$E$22*0.9173,0) -> 64640.014 | P9: =IFERROR((G9*12)/O9,0) -> 10.901559 | Q9: =IFERROR(365/P9,0) -> 33.48145
A10: Mar-2026 | B10: Executive & Corporate Services | C10: =Assumptions!$B$5*Assumptions!$B$10*Assumptions!$B$29/Assumptions!$B$39 -> 284188.03 | D10: =C10*1.0885 -> 309338.68 | E10: =IFERROR(D10/C10,0) -> 1.0885 | F10: =Assumptions!$B$19 -> 0.55 | G10: =D10*F10 -> 170136.27 | H10: =D10-G10 -> 139202.4 | I10: =IFERROR(H10/D10,0) -> 0.45 | J10: =Assumptions!$C$19 -> 0.85 | K10: =D10*J10 -> 262937.87 | L10: =(Assumptions!$D$19/Assumptions!$C$29)*K10*0.951 -> 362981.49 | M10: =Assumptions!$C$29 -> 31 | N10: =IFERROR((L10/K10)*M10,0) -> 42.795 | O10: =IFERROR((G10*12)/Assumptions!$E$19*0.9023,0) -> 230270.94 | P10: =IFERROR((G10*12)/O10,0) -> 8.8662307 | Q10: =IFERROR(365/P10,0) -> 41.167437
A11: Mar-2026 | B11: Client Operations & Revenue Recovery | C11: =Assumptions!$B$5*Assumptions!$B$11*Assumptions!$B$29/Assumptions!$B$39 -> 243589.74 | D11: =C11*0.9185 -> 223737.18 | E11: =IFERROR(D11/C11,0) -> 0.9185 | F11: =Assumptions!$B$20 -> 0.6 | G11: =D11*F11 -> 134242.31 | H11: =D11-G11 -> 89494.872 | I11: =IFERROR(H11/D11,0) -> 0.4 | J11: =Assumptions!$C$20 -> 0.9 | K11: =D11*J11 -> 201363.46 | L11: =(Assumptions!$D$20/Assumptions!$C$29)*K11*1.1042 -> 358621.83 | M11: =Assumptions!$C$29 -> 31 | N11: =IFERROR((L11/K11)*M11,0) -> 55.21 | O11: =IFERROR((G11*12)/Assumptions!$E$20*1.0249,0) -> 275169.88 | P11: =IFERROR((G11*12)/O11,0) -> 5.8542297 | Q11: =IFERROR(365/P11,0) -> 62.348083
A12: Mar-2026 | B12: Product & Technology (Atrium) | C12: =Assumptions!$B$5*Assumptions!$B$12*Assumptions!$B$29/Assumptions!$B$39 -> 162393.16 | D12: =C12*1.0624 -> 172526.5 | E12: =IFERROR(D12/C12,0) -> 1.0624 | F12: =Assumptions!$B$21 -> 0.4 | G12: =D12*F12 -> 69010.598 | H12: =D12-G12 -> 103515.9 | I12: =IFERROR(H12/D12,0) -> 0.6 | J12: =Assumptions!$C$21 -> 0.7 | K12: =D12*J12 -> 120768.55 | L12: =(Assumptions!$D$21/Assumptions!$C$29)*K12*1.0689 -> 124925.32 | M12: =Assumptions!$C$29 -> 31 | N12: =IFERROR((L12/K12)*M12,0) -> 32.067 | O12: =IFERROR((G12*12)/Assumptions!$E$21*1.0087,0) -> 69610.99 | P12: =IFERROR((G12*12)/O12,0) -> 11.8965 | Q12: =IFERROR(365/P12,0) -> 30.681292
A13: Mar-2026 | B13: Consulting & Advisory | C13: =Assumptions!$B$5*Assumptions!$B$13*Assumptions!$B$29/Assumptions!$B$39 -> 121794.87 | D13: =C13*1.0976 -> 133682.05 | E13: =IFERROR(D13/C13,0) -> 1.0976 | F13: =Assumptions!$B$22 -> 0.5 | G13: =D13*F13 -> 66841.026 | H13: =D13-G13 -> 66841.026 | I13: =IFERROR(H13/D13,0) -> 0.5 | J13: =Assumptions!$C$22 -> 0.8 | K13: =D13*J13 -> 106945.64 | L13: =(Assumptions!$D$22/Assumptions!$C$29)*K13*0.9636 -> 132971.38 | M13: =Assumptions!$C$29 -> 31 | N13: =IFERROR((L13/K13)*M13,0) -> 38.544 | O13: =IFERROR((G13*12)/Assumptions!$E$22*1.0125,0) -> 81211.846 | P13: =IFERROR((G13*12)/O13,0) -> 9.8765432 | Q13: =IFERROR(365/P13,0) -> 36.95625
A14: Apr-2026 | B14: Executive & Corporate Services | C14: =Assumptions!$B$5*Assumptions!$B$10*Assumptions!$B$30/Assumptions!$B$39 -> 275213.68 | D14: =C14*1.0615 -> 292139.32 | E14: =IFERROR(D14/C14,0) -> 1.0615 | F14: =Assumptions!$B$19 -> 0.55 | G14: =D14*F14 -> 160676.62 | H14: =D14-G14 -> 131462.69 | I14: =IFERROR(H14/D14,0) -> 0.45 | J14: =Assumptions!$C$19 -> 0.85 | K14: =D14*J14 -> 248318.42 | L14: =(Assumptions!$D$19/Assumptions!$C$30)*K14*1.0356 -> 385737.83 | M14: =Assumptions!$C$30 -> 30 | N14: =IFERROR((L14/K14)*M14,0) -> 46.602 | O14: =IFERROR((G14*12)/Assumptions!$E$19*1.0868,0) -> 261935.03 | P14: =IFERROR((G14*12)/O14,0) -> 7.36106 | Q14: =IFERROR(365/P14,0) -> 49.58525
A15: Apr-2026 | B15: Client Operations & Revenue Recovery | C15: =Assumptions!$B$5*Assumptions!$B$11*Assumptions!$B$30/Assumptions!$B$39 -> 235897.44 | D15: =C15*1.0141 -> 239223.59 | E15: =IFERROR(D15/C15,0) -> 1.0141 | F15: =Assumptions!$B$20 -> 0.6 | G15: =D15*F15 -> 143534.15 | H15: =D15-G15 -> 95689.436 | I15: =IFERROR(H15/D15,0) -> 0.4 | J15: =Assumptions!$C$20 -> 0.9 | K15: =D15*J15 -> 215301.23 | L15: =(Assumptions!$D$20/Assumptions!$C$30)*K15*1.0614 -> 380867.88 | M15: =Assumptions!$C$30 -> 30 | N15: =IFERROR((L15/K15)*M15,0) -> 53.07 | O15: =IFERROR((G15*12)/Assumptions!$E$20*0.891,0) -> 255777.86 | P15: =IFERROR((G15*12)/O15,0) -> 6.7340067 | Q15: =IFERROR(365/P15,0) -> 54.2025
A16: Apr-2026 | B16: Product & Technology (Atrium) | C16: =Assumptions!$B$5*Assumptions!$B$12*Assumptions!$B$30/Assumptions!$B$39 -> 157264.96 | D16: =C16*0.9469 -> 148914.19 | E16: =IFERROR(D16/C16,0) -> 0.9469 | F16: =Assumptions!$B$21 -> 0.4 | G16: =D16*F16 -> 59565.675 | H16: =D16-G16 -> 89348.513 | I16: =IFERROR(H16/D16,0) -> 0.6 | J16: =Assumptions!$C$21 -> 0.7 | K16: =D16*J16 -> 104239.93 | L16: =(Assumptions!$D$21/Assumptions!$C$30)*K16*0.9368 -> 97651.968 | M16: =Assumptions!$C$30 -> 30 | N16: =IFERROR((L16/K16)*M16,0) -> 28.104 | O16: =IFERROR((G16*12)/Assumptions!$E$21*0.8992,0) -> 53561.455 | P16: =IFERROR((G16*12)/O16,0) -> 13.345196 | Q16: =IFERROR(365/P16,0) -> 27.350667
A17: Apr-2026 | B17: Consulting & Advisory | C17: =Assumptions!$B$5*Assumptions!$B$13*Assumptions!$B$30/Assumptions!$B$39 -> 117948.72 | D17: =C17*0.9504 -> 112098.46 | E17: =IFERROR(D17/C17,0) -> 0.9504 | F17: =Assumptions!$B$22 -> 0.5 | G17: =D17*F17 -> 56049.231 | H17: =D17-G17 -> 56049.231 | I17: =IFERROR(H17/D17,0) -> 0.5 | J17: =Assumptions!$C$22 -> 0.8 | K17: =D17*J17 -> 89678.769 | L17: =(Assumptions!$D$22/Assumptions!$C$30)*K17*0.8803 -> 105258.96 | M17: =Assumptions!$C$30 -> 30 | N17: =IFERROR((L17/K17)*M17,0) -> 35.212 | O17: =IFERROR((G17*12)/Assumptions!$E$22*0.9467,0) -> 63674.168 | P17: =IFERROR((G17*12)/O17,0) -> 10.563008 | Q17: =IFERROR(365/P17,0) -> 34.55455
A18: May-2026 | B18: Executive & Corporate Services | C18: =Assumptions!$B$5*Assumptions!$B$10*Assumptions!$B$31/Assumptions!$B$39 -> 269230.77 | D18: =C18*1.0215 -> 275019.23 | E18: =IFERROR(D18/C18,0) -> 1.0215 | F18: =Assumptions!$B$19 -> 0.55 | G18: =D18*F18 -> 151260.58 | H18: =D18-G18 -> 123758.65 | I18: =IFERROR(H18/D18,0) -> 0.45 | J18: =Assumptions!$C$19 -> 0.85 | K18: =D18*J18 -> 233766.35 | L18: =(Assumptions!$D$19/Assumptions!$C$31)*K18*0.9594 -> 325561.11 | M18: =Assumptions!$C$31 -> 31 | N18: =IFERROR((L18/K18)*M18,0) -> 43.173 | O18: =IFERROR((G18*12)/Assumptions!$E$19*0.9688,0) -> 219811.87 | P18: =IFERROR((G18*12)/O18,0) -> 8.2576383 | Q18: =IFERROR(365/P18,0) -> 44.2015
A19: May-2026 | B19: Client Operations & Revenue Recovery | C19: =Assumptions!$B$5*Assumptions!$B$11*Assumptions!$B$31/Assumptions!$B$39 -> 230769.23 | D19: =C19*0.9402 -> 216969.23 | E19: =IFERROR(D19/C19,0) -> 0.9402 | F19: =Assumptions!$B$20 -> 0.6 | G19: =D19*F19 -> 130181.54 | H19: =D19-G19 -> 86787.692 | I19: =IFERROR(H19/D19,0) -> 0.4 | J19: =Assumptions!$C$20 -> 0.9 | K19: =D19*J19 -> 195272.31 | L19: =(Assumptions!$D$20/Assumptions!$C$31)*K19*0.9301 -> 292939.96 | M19: =Assumptions!$C$31 -> 31 | N19: =IFERROR((L19/K19)*M19,0) -> 46.505 | O19: =IFERROR((G19*12)/Assumptions!$E$20*1.1048,0) -> 287649.13 | P19: =IFERROR((G19*12)/O19,0) -> 5.4308472 | Q19: =IFERROR(365/P19,0) -> 67.208667
A20: May-2026 | B20: Product & Technology (Atrium) | C20: =Assumptions!$B$5*Assumptions!$B$12*Assumptions!$B$31/Assumptions!$B$39 -> 153846.15 | D20: =C20*1.0315 -> 158692.31 | E20: =IFERROR(D20/C20,0) -> 1.0315 | F20: =Assumptions!$B$21 -> 0.4 | G20: =D20*F20 -> 63476.923 | H20: =D20-G20 -> 95215.385 | I20: =IFERROR(H20/D20,0) -> 0.6 | J20: =Assumptions!$C$21 -> 0.7 | K20: =D20*J20 -> 111084.62 | L20: =(Assumptions!$D$21/Assumptions!$C$31)*K20*1.0327 -> 111016.53 | M20: =Assumptions!$C$31 -> 31 | N20: =IFERROR((L20/K20)*M20,0) -> 30.981 | O20: =IFERROR((G20*12)/Assumptions!$E$21*0.9211,0) -> 58468.594 | P20: =IFERROR((G20*12)/O20,0) -> 13.027901 | Q20: =IFERROR(365/P20,0) -> 28.016792
A21: May-2026 | B21: Consulting & Advisory | C21: =Assumptions!$B$5*Assumptions!$B$13*Assumptions!$B$31/Assumptions!$B$39 -> 115384.62 | D21: =C21*1.0515 -> 121326.92 | E21: =IFERROR(D21/C21,0) -> 1.0515 | F21: =Assumptions!$B$22 -> 0.5 | G21: =D21*F21 -> 60663.462 | H21: =D21-G21 -> 60663.462 | I21: =IFERROR(H21/D21,0) -> 0.5 | J21: =Assumptions!$C$22 -> 0.8 | K21: =D21*J21 -> 97061.538 | L21: =(Assumptions!$D$22/Assumptions!$C$31)*K21*0.899 -> 112591.38 | M21: =Assumptions!$C$31 -> 31 | N21: =IFERROR((L21/K21)*M21,0) -> 35.96 | O21: =IFERROR((G21*12)/Assumptions!$E$22*0.9711,0) -> 70692.345 | P21: =IFERROR((G21*12)/O21,0) -> 10.297601 | Q21: =IFERROR(365/P21,0) -> 35.44515
A22: Jun-2026 | B22: Executive & Corporate Services | C22: =Assumptions!$B$5*Assumptions!$B$10*Assumptions!$B$32/Assumptions!$B$39 -> 239316.24 | D22: =C22*1.0904 -> 260950.43 | E22: =IFERROR(D22/C22,0) -> 1.0904 | F22: =Assumptions!$B$19 -> 0.55 | G22: =D22*F22 -> 143522.74 | H22: =D22-G22 -> 117427.69 | I22: =IFERROR(H22/D22,0) -> 0.45 | J22: =Assumptions!$C$19 -> 0.85 | K22: =D22*J22 -> 221807.86 | L22: =(Assumptions!$D$19/Assumptions!$C$32)*K22*1.042 -> 346685.69 | M22: =Assumptions!$C$32 -> 30 | N22: =IFERROR((L22/K22)*M22,0) -> 46.89 | O22: =IFERROR((G22*12)/Assumptions!$E$19*1.0137,0) -> 218233.49 | P22: =IFERROR((G22*12)/O22,0) -> 7.8918812 | Q22: =IFERROR(365/P22,0) -> 46.250062
A23: Jun-2026 | B23: Client Operations & Revenue Recovery | C23: =Assumptions!$B$5*Assumptions!$B$11*Assumptions!$B$32/Assumptions!$B$39 -> 205128.21 | D23: =C23*1.0346 -> 212225.64 | E23: =IFERROR(D23/C23,0) -> 1.0346 | F23: =Assumptions!$B$20 -> 0.6 | G23: =D23*F23 -> 127335.38 | H23: =D23-G23 -> 84890.256 | I23: =IFERROR(H23/D23,0) -> 0.4 | J23: =Assumptions!$C$20 -> 0.9 | K23: =D23*J23 -> 191003.08 | L23: =(Assumptions!$D$20/Assumptions!$C$32)*K23*1.1029 -> 351095.49 | M23: =Assumptions!$C$32 -> 30 | N23: =IFERROR((L23/K23)*M23,0) -> 55.145 | O23: =IFERROR((G23*12)/Assumptions!$E$20*1.0662,0) -> 271529.97 | P23: =IFERROR((G23*12)/O23,0) -> 5.627462 | Q23: =IFERROR(365/P23,0) -> 64.8605
A24: Jun-2026 | B24: Product & Technology (Atrium) | C24: =Assumptions!$B$5*Assumptions!$B$12*Assumptions!$B$32/Assumptions!$B$39 -> 136752.14 | D24: =C24*0.948 -> 129641.03 | E24: =IFERROR(D24/C24,0) -> 0.948 | F24: =Assumptions!$B$21 -> 0.4 | G24: =D24*F24 -> 51856.41 | H24: =D24-G24 -> 77784.615 | I24: =IFERROR(H24/D24,0) -> 0.6 | J24: =Assumptions!$C$21 -> 0.7 | K24: =D24*J24 -> 90748.718 | L24: =(Assumptions!$D$21/Assumptions!$C$32)*K24*0.8596 -> 78007.598 | M24: =Assumptions!$C$32 -> 30 | N24: =IFERROR((L24/K24)*M24,0) -> 25.788 | O24: =IFERROR((G24*12)/Assumptions!$E$21*0.9557,0) -> 49559.171 | P24: =IFERROR((G24*12)/O24,0) -> 12.556241 | Q24: =IFERROR(365/P24,0) -> 29.069208
A25: Jun-2026 | B25: Consulting & Advisory | C25: =Assumptions!$B$5*Assumptions!$B$13*Assumptions!$B$32/Assumptions!$B$39 -> 102564.1 | D25: =C25*0.96 -> 98461.538 | E25: =IFERROR(D25/C25,0) -> 0.96 | F25: =Assumptions!$B$22 -> 0.5 | G25: =D25*F25 -> 49230.769 | H25: =D25-G25 -> 49230.769 | I25: =IFERROR(H25/D25,0) -> 0.5 | J25: =Assumptions!$C$22 -> 0.8 | K25: =D25*J25 -> 78769.231 | L25: =(Assumptions!$D$22/Assumptions!$C$32)*K25*0.9133 -> 95919.918 | M25: =Assumptions!$C$32 -> 30 | N25: =IFERROR((L25/K25)*M25,0) -> 36.532 | O25: =IFERROR((G25*12)/Assumptions!$E$22*1.1063,0) -> 65356.8 | P25: =IFERROR((G25*12)/O25,0) -> 9.0391395 | Q25: =IFERROR(365/P25,0) -> 40.37995
A26: Jul-2026 | B26: Executive & Corporate Services | C26: =Assumptions!$B$5*Assumptions!$B$10*Assumptions!$B$33/Assumptions!$B$39 -> 224358.97 | D26: =C26*1.0665 -> 239278.85 | E26: =IFERROR(D26/C26,0) -> 1.0665 | F26: =Assumptions!$B$19 -> 0.55 | G26: =D26*F26 -> 131603.37 | H26: =D26-G26 -> 107675.48 | I26: =IFERROR(H26/D26,0) -> 0.45 | J26: =Assumptions!$C$19 -> 0.85 | K26: =D26*J26 -> 203387.02 | L26: =(Assumptions!$D$19/Assumptions!$C$33)*K26*0.9444 -> 278823.92 | M26: =Assumptions!$C$33 -> 31 | N26: =IFERROR((L26/K26)*M26,0) -> 42.498 | O26: =IFERROR((G26*12)/Assumptions!$E$19*1.0373,0) -> 204768.26 | P26: =IFERROR((G26*12)/O26,0) -> 7.7123301 | Q26: =IFERROR(365/P26,0) -> 47.326813
A27: Jul-2026 | B27: Client Operations & Revenue Recovery | C27: =Assumptions!$B$5*Assumptions!$B$11*Assumptions!$B$33/Assumptions!$B$39 -> 192307.69 | D27: =C27*0.9765 -> 187788.46 | E27: =IFERROR(D27/C27,0) -> 0.9765 | F27: =Assumptions!$B$20 -> 0.6 | G27: =D27*F27 -> 112673.08 | H27: =D27-G27 -> 75115.385 | I27: =IFERROR(H27/D27,0) -> 0.4 | J27: =Assumptions!$C$20 -> 0.9 | K27: =D27*J27 -> 169009.62 | L27: =(Assumptions!$D$20/Assumptions!$C$33)*K27*1.1244 -> 306507.12 | M27: =Assumptions!$C$33 -> 31 | N27: =IFERROR((L27/K27)*M27,0) -> 56.22 | O27: =IFERROR((G27*12)/Assumptions!$E$20*0.9901,0) -> 223115.23 | P27: =IFERROR((G27*12)/O27,0) -> 6.0599939 | Q27: =IFERROR(365/P27,0) -> 60.231083
A28: Jul-2026 | B28: Product & Technology (Atrium) | C28: =Assumptions!$B$5*Assumptions!$B$12*Assumptions!$B$33/Assumptions!$B$39 -> 128205.13 | D28: =C28*0.9556 -> 122512.82 | E28: =IFERROR(D28/C28,0) -> 0.9556 | F28: =Assumptions!$B$21 -> 0.4 | G28: =D28*F28 -> 49005.128 | H28: =D28-G28 -> 73507.692 | I28: =IFERROR(H28/D28,0) -> 0.6 | J28: =Assumptions!$C$21 -> 0.7 | K28: =D28*J28 -> 85758.974 | L28: =(Assumptions!$D$21/Assumptions!$C$33)*K28*0.924 -> 76685.122 | M28: =Assumptions!$C$33 -> 31 | N28: =IFERROR((L28/K28)*M28,0) -> 27.72 | O28: =IFERROR((G28*12)/Assumptions!$E$21*1.0147,0) -> 49725.504 | P28: =IFERROR((G28*12)/O28,0) -> 11.826156 | Q28: =IFERROR(365/P28,0) -> 30.863792
A29: Jul-2026 | B29: Consulting & Advisory | C29: =Assumptions!$B$5*Assumptions!$B$13*Assumptions!$B$33/Assumptions!$B$39 -> 96153.846 | D29: =C29*0.9603 -> 92336.538 | E29: =IFERROR(D29/C29,0) -> 0.9603 | F29: =Assumptions!$B$22 -> 0.5 | G29: =D29*F29 -> 46168.269 | H29: =D29-G29 -> 46168.269 | I29: =IFERROR(H29/D29,0) -> 0.5 | J29: =Assumptions!$C$22 -> 0.8 | K29: =D29*J29 -> 73869.231 | L29: =(Assumptions!$D$22/Assumptions!$C$33)*K29*1.0254 -> 97736.141 | M29: =Assumptions!$C$33 -> 31 | N29: =IFERROR((L29/K29)*M29,0) -> 41.016 | O29: =IFERROR((G29*12)/Assumptions!$E$22*1.0955,0) -> 60692.807 | P29: =IFERROR((G29*12)/O29,0) -> 9.1282519 | Q29: =IFERROR(365/P29,0) -> 39.98575
A30: Aug-2026 | B30: Executive & Corporate Services | C30: =Assumptions!$B$5*Assumptions!$B$10*Assumptions!$B$34/Assumptions!$B$39 -> 239316.24 | D30: =C30*0.9705 -> 232256.41 | E30: =IFERROR(D30/C30,0) -> 0.9705 | F30: =Assumptions!$B$19 -> 0.55 | G30: =D30*F30 -> 127741.03 | H30: =D30-G30 -> 104515.38 | I30: =IFERROR(H30/D30,0) -> 0.45 | J30: =Assumptions!$C$19 -> 0.85 | K30: =D30*J30 -> 197417.95 | L30: =(Assumptions!$D$19/Assumptions!$C$34)*K30*0.9158 -> 262444.87 | M30: =Assumptions!$C$34 -> 31 | N30: =IFERROR((L30/K30)*M30,0) -> 41.211 | O30: =IFERROR((G30*12)/Assumptions!$E$19*1.1194,0) -> 214489.96 | P30: =IFERROR((G30*12)/O30,0) -> 7.1466857 | Q30: =IFERROR(365/P30,0) -> 51.072625
A31: Aug-2026 | B31: Client Operations & Revenue Recovery | C31: =Assumptions!$B$5*Assumptions!$B$11*Assumptions!$B$34/Assumptions!$B$39 -> 205128.21 | D31: =C31*0.9987 -> 204861.54 | E31: =IFERROR(D31/C31,0) -> 0.9987 | F31: =Assumptions!$B$20 -> 0.6 | G31: =D31*F31 -> 122916.92 | H31: =D31-G31 -> 81944.615 | I31: =IFERROR(H31/D31,0) -> 0.4 | J31: =Assumptions!$C$20 -> 0.9 | K31: =D31*J31 -> 184375.38 | L31: =(Assumptions!$D$20/Assumptions!$C$34)*K31*0.8773 -> 260891.17 | M31: =Assumptions!$C$34 -> 31 | N31: =IFERROR((L31/K31)*M31,0) -> 43.865 | O31: =IFERROR((G31*12)/Assumptions!$E$20*0.8913,0) -> 219111.71 | P31: =IFERROR((G31*12)/O31,0) -> 6.7317402 | Q31: =IFERROR(365/P31,0) -> 54.22075
A32: Aug-2026 | B32: Product & Technology (Atrium) | C32: =Assumptions!$B$5*Assumptions!$B$12*Assumptions!$B$34/Assumptions!$B$39 -> 136752.14 | D32: =C32*0.9249 -> 126482.05 | E32: =IFERROR(D32/C32,0) -> 0.9249 | F32: =Assumptions!$B$21 -> 0.4 | G32: =D32*F32 -> 50592.821 | H32: =D32-G32 -> 75889.231 | I32: =IFERROR(H32/D32,0) -> 0.6 | J32: =Assumptions!$C$21 -> 0.7 | K32: =D32*J32 -> 88537.436 | L32: =(Assumptions!$D$21/Assumptions!$C$34)*K32*1.0382 -> 88954.419 | M32: =Assumptions!$C$34 -> 31 | N32: =IFERROR((L32/K32)*M32,0) -> 31.146 | O32: =IFERROR((G32*12)/Assumptions!$E$21*1.0701,0) -> 54139.377 | P32: =IFERROR((G32*12)/O32,0) -> 11.213905 | Q32: =IFERROR(365/P32,0) -> 32.548875
A33: Aug-2026 | B33: Consulting & Advisory | C33: =Assumptions!$B$5*Assumptions!$B$13*Assumptions!$B$34/Assumptions!$B$39 -> 102564.1 | D33: =C33*0.9938 -> 101928.21 | E33: =IFERROR(D33/C33,0) -> 0.9938 | F33: =Assumptions!$B$22 -> 0.5 | G33: =D33*F33 -> 50964.103 | H33: =D33-G33 -> 50964.103 | I33: =IFERROR(H33/D33,0) -> 0.5 | J33: =Assumptions!$C$22 -> 0.8 | K33: =D33*J33 -> 81542.564 | L33: =(Assumptions!$D$22/Assumptions!$C$34)*K33*0.8691 -> 91443.41 | M33: =Assumptions!$C$34 -> 31 | N33: =IFERROR((L33/K33)*M33,0) -> 34.764 | O33: =IFERROR((G33*12)/Assumptions!$E$22*0.9716,0) -> 59420.066 | P33: =IFERROR((G33*12)/O33,0) -> 10.292301 | Q33: =IFERROR(365/P33,0) -> 35.4634
A34: Sep-2026 | B34: Executive & Corporate Services | C34: =Assumptions!$B$5*Assumptions!$B$10*Assumptions!$B$35/Assumptions!$B$39 -> 314102.56 | D34: =C34*1.0872 -> 341492.31 | E34: =IFERROR(D34/C34,0) -> 1.0872 | F34: =Assumptions!$B$19 -> 0.55 | G34: =D34*F34 -> 187820.77 | H34: =D34-G34 -> 153671.54 | I34: =IFERROR(H34/D34,0) -> 0.45 | J34: =Assumptions!$C$19 -> 0.85 | K34: =D34*J34 -> 290268.46 | L34: =(Assumptions!$D$19/Assumptions!$C$35)*K34*1.0087 -> 439190.7 | M34: =Assumptions!$C$35 -> 30 | N34: =IFERROR((L34/K34)*M34,0) -> 45.3915 | O34: =IFERROR((G34*12)/Assumptions!$E$19*1.1131,0) -> 313594.95 | P34: =IFERROR((G34*12)/O34,0) -> 7.187135 | Q34: =IFERROR(365/P34,0) -> 50.785187
A35: Sep-2026 | B35: Client Operations & Revenue Recovery | C35: =Assumptions!$B$5*Assumptions!$B$11*Assumptions!$B$35/Assumptions!$B$39 -> 269230.77 | D35: =C35*1.0683 -> 287619.23 | E35: =IFERROR(D35/C35,0) -> 1.0683 | F35: =Assumptions!$B$20 -> 0.6 | G35: =D35*F35 -> 172571.54 | H35: =D35-G35 -> 115047.69 | I35: =IFERROR(H35/D35,0) -> 0.4 | J35: =Assumptions!$C$20 -> 0.9 | K35: =D35*J35 -> 258857.31 | L35: =(Assumptions!$D$20/Assumptions!$C$35)*K35*0.8534 -> 368181.38 | M35: =Assumptions!$C$35 -> 30 | N35: =IFERROR((L35/K35)*M35,0) -> 42.67 | O35: =IFERROR((G35*12)/Assumptions!$E$20*1.053,0) -> 363435.66 | P35: =IFERROR((G35*12)/O35,0) -> 5.6980057 | Q35: =IFERROR(365/P35,0) -> 64.0575
A36: Sep-2026 | B36: Product & Technology (Atrium) | C36: =Assumptions!$B$5*Assumptions!$B$12*Assumptions!$B$35/Assumptions!$B$39 -> 179487.18 | D36: =C36*1.0401 -> 186684.62 | E36: =IFERROR(D36/C36,0) -> 1.0401 | F36: =Assumptions!$B$21 -> 0.4 | G36: =D36*F36 -> 74673.846 | H36: =D36-G36 -> 112010.77 | I36: =IFERROR(H36/D36,0) -> 0.6 | J36: =Assumptions!$C$21 -> 0.7 | K36: =D36*J36 -> 130679.23 | L36: =(Assumptions!$D$21/Assumptions!$C$35)*K36*1.0111 -> 132129.77 | M36: =Assumptions!$C$35 -> 30 | N36: =IFERROR((L36/K36)*M36,0) -> 30.333 | O36: =IFERROR((G36*12)/Assumptions!$E$21*0.944,0) -> 70492.111 | P36: =IFERROR((G36*12)/O36,0) -> 12.711864 | Q36: =IFERROR(365/P36,0) -> 28.713333
A37: Sep-2026 | B37: Consulting & Advisory | C37: =Assumptions!$B$5*Assumptions!$B$13*Assumptions!$B$35/Assumptions!$B$39 -> 134615.38 | D37: =C37*1.0394 -> 139919.23 | E37: =IFERROR(D37/C37,0) -> 1.0394 | F37: =Assumptions!$B$22 -> 0.5 | G37: =D37*F37 -> 69959.615 | H37: =D37-G37 -> 69959.615 | I37: =IFERROR(H37/D37,0) -> 0.5 | J37: =Assumptions!$C$22 -> 0.8 | K37: =D37*J37 -> 111935.38 | L37: =(Assumptions!$D$22/Assumptions!$C$35)*K37*0.8835 -> 131859.88 | M37: =Assumptions!$C$35 -> 30 | N37: =IFERROR((L37/K37)*M37,0) -> 35.34 | O37: =IFERROR((G37*12)/Assumptions!$E$22*0.9843,0) -> 82633.499 | P37: =IFERROR((G37*12)/O37,0) -> 10.159504 | Q37: =IFERROR(365/P37,0) -> 35.92695
A38: Oct-2026 | B38: Executive & Corporate Services | C38: =Assumptions!$B$5*Assumptions!$B$10*Assumptions!$B$36/Assumptions!$B$39 -> 344017.09 | D38: =C38*0.9786 -> 336655.13 | E38: =IFERROR(D38/C38,0) -> 0.9786 | F38: =Assumptions!$B$19 -> 0.55 | G38: =D38*F38 -> 185160.32 | H38: =D38-G38 -> 151494.81 | I38: =IFERROR(H38/D38,0) -> 0.45 | J38: =Assumptions!$C$19 -> 0.85 | K38: =D38*J38 -> 286156.86 | L38: =(Assumptions!$D$19/Assumptions!$C$36)*K38*1.1361 -> 471923.43 | M38: =Assumptions!$C$36 -> 31 | N38: =IFERROR((L38/K38)*M38,0) -> 51.1245 | O38: =IFERROR((G38*12)/Assumptions!$E$19*1.0902,0) -> 302792.67 | P38: =IFERROR((G38*12)/O38,0) -> 7.3381031 | Q38: =IFERROR(365/P38,0) -> 49.740375
A39: Oct-2026 | B39: Client Operations & Revenue Recovery | C39: =Assumptions!$B$5*Assumptions!$B$11*Assumptions!$B$36/Assumptions!$B$39 -> 294871.79 | D39: =C39*0.9488 -> 279774.36 | E39: =IFERROR(D39/C39,0) -> 0.9488 | F39: =Assumptions!$B$20 -> 0.6 | G39: =D39*F39 -> 167864.62 | H39: =D39-G39 -> 111909.74 | I39: =IFERROR(H39/D39,0) -> 0.4 | J39: =Assumptions!$C$20 -> 0.9 | K39: =D39*J39 -> 251796.92 | L39: =(Assumptions!$D$20/Assumptions!$C$36)*K39*1.0002 -> 406205.29 | M39: =Assumptions!$C$36 -> 31 | N39: =IFERROR((L39/K39)*M39,0) -> 50.01 | O39: =IFERROR((G39*12)/Assumptions!$E$20*0.9229,0) -> 309844.51 | P39: =IFERROR((G39*12)/O39,0) -> 6.5012461 | Q39: =IFERROR(365/P39,0) -> 56.143083
A40: Oct-2026 | B40: Product & Technology (Atrium) | C40: =Assumptions!$B$5*Assumptions!$B$12*Assumptions!$B$36/Assumptions!$B$39 -> 196581.2 | D40: =C40*1.087 -> 213683.76 | E40: =IFERROR(D40/C40,0) -> 1.087 | F40: =Assumptions!$B$21 -> 0.4 | G40: =D40*F40 -> 85473.504 | H40: =D40-G40 -> 128210.26 | I40: =IFERROR(H40/D40,0) -> 0.6 | J40: =Assumptions!$C$21 -> 0.7 | K40: =D40*J40 -> 149578.63 | L40: =(Assumptions!$D$21/Assumptions!$C$36)*K40*1.1112 -> 160850.11 | M40: =Assumptions!$C$36 -> 31 | N40: =IFERROR((L40/K40)*M40,0) -> 33.336 | O40: =IFERROR((G40*12)/Assumptions!$E$21*0.9516,0) -> 81336.587 | P40: =IFERROR((G40*12)/O40,0) -> 12.61034 | Q40: =IFERROR(365/P40,0) -> 28.9445
...

Sheet KPI Tracker
A1: Company KPI Tracker
A2: Monthly rollup — every cell below is aggregated live from Monthly Data via SUMIFS/AVERAGEIFS.
A4: Month | B4: Revenue Target (AED) | C4: Revenue Actual (AED) | D4: Achievement % | E4: Variance (AED) | F4: Total COGS (AED) | G4: Gross Profit (AED) | H4: Gross Margin % | I4: Total Credit Sales (AED) | J4: Closing Receivables (AED) | K4: Company DSO (Days) | L4: Average Inventory (AED) | M4: Inventory Turnover (x)
A5: Jan-2026 | B5: =SUMIF('Monthly Data'!$A$2:$A$49,$A5,'Monthly Data'!$C$2:$C$49) -> 769230.77 | C5: =SUMIF('Monthly Data'!$A$2:$A$49,$A5,'Monthly Data'!$D$2:$D$49) -> 765173.08 | D5: =IFERROR(C5/B5,0) -> 0.994725 | E5: =C5-B5 -> -4057.6923 | F5: =SUMIF('Monthly Data'!$A$2:$A$49,$A5,'Monthly Data'!$G$2:$G$49) -> 401631.35 | G5: =SUMIF('Monthly Data'!$A$2:$A$49,$A5,'Monthly Data'!$H$2:$H$49) -> 363541.73 | H5: =IFERROR(G5/C5,0) -> 0.47511046 | I5: =SUMIF('Monthly Data'!$A$2:$A$49,$A5,'Monthly Data'!$K$2:$K$49) -> 631183.27 | J5: =SUMIF('Monthly Data'!$A$2:$A$49,$A5,'Monthly Data'!$L$2:$L$49) -> 828936.84 | K5: =IFERROR((J5/I5)*AVERAGEIF('Monthly Data'!$A$2:$A$49,$A5,'Monthly Data'!$M$2:$M$49),0) -> 40.712489 | L5: =SUMIF('Monthly Data'!$A$2:$A$49,$A5,'Monthly Data'!$O$2:$O$49) -> 616582.83 | M5: =IFERROR((F5*12)/L5,0) -> 7.8165915
A6: Feb-2026 | B6: =SUMIF('Monthly Data'!$A$2:$A$49,$A6,'Monthly Data'!$C$2:$C$49) -> 752136.75 | C6: =SUMIF('Monthly Data'!$A$2:$A$49,$A6,'Monthly Data'!$D$2:$D$49) -> 742821.54 | D6: =IFERROR(C6/B6,0) -> 0.987615 | E6: =C6-B6 -> -9315.2137 | F6: =SUMIF('Monthly Data'!$A$2:$A$49,$A6,'Monthly Data'!$G$2:$G$49) -> 390085.38 | G6: =SUMIF('Monthly Data'!$A$2:$A$49,$A6,'Monthly Data'!$H$2:$H$49) -> 352736.15 | H6: =IFERROR(G6/C6,0) -> 0.47485989 | I6: =SUMIF('Monthly Data'!$A$2:$A$49,$A6,'Monthly Data'!$K$2:$K$49) -> 612931.85 | J6: =SUMIF('Monthly Data'!$A$2:$A$49,$A6,'Monthly Data'!$L$2:$L$49) -> 860709.09 | K6: =IFERROR((J6/I6)*AVERAGEIF('Monthly Data'!$A$2:$A$49,$A6,'Monthly Data'!$M$2:$M$49),0) -> 39.318979 | L6: =SUMIF('Monthly Data'!$A$2:$A$49,$A6,'Monthly Data'!$O$2:$O$49) -> 615592.89 | M6: =IFERROR((F6*12)/L6,0) -> 7.6040914
A7: Mar-2026 | B7: =SUMIF('Monthly Data'!$A$2:$A$49,$A7,'Monthly Data'!$C$2:$C$49) -> 811965.81 | C7: =SUMIF('Monthly Data'!$A$2:$A$49,$A7,'Monthly Data'!$D$2:$D$49) -> 839284.4 | D7: =IFERROR(C7/B7,0) -> 1.033645 | E7: =C7-B7 -> 27318.59 | F7: =SUMIF('Monthly Data'!$A$2:$A$49,$A7,'Monthly Data'!$G$2:$G$49) -> 440230.2 | G7: =SUMIF('Monthly Data'!$A$2:$A$49,$A7,'Monthly Data'!$H$2:$H$49) -> 399054.2 | H7: =IFERROR(G7/C7,0) -> 0.47546958 | I7: =SUMIF('Monthly Data'!$A$2:$A$49,$A7,'Monthly Data'!$K$2:$K$49) -> 692015.52 | J7: =SUMIF('Monthly Data'!$A$2:$A$49,$A7,'Monthly Data'!$L$2:$L$49) -> 979500.03 | K7: =IFERROR((J7/I7)*AVERAGEIF('Monthly Data'!$A$2:$A$49,$A7,'Monthly Data'!$M$2:$M$49),0) -> 43.878352 | L7: =SUMIF('Monthly Data'!$A$2:$A$49,$A7,'Monthly Data'!$O$2:$O$49) -> 656263.66 | M7: =IFERROR((F7*12)/L7,0) -> 8.0497562
A8: Apr-2026 | B8: =SUMIF('Monthly Data'!$A$2:$A$49,$A8,'Monthly Data'!$C$2:$C$49) -> 786324.79 | C8: =SUMIF('Monthly Data'!$A$2:$A$49,$A8,'Monthly Data'!$D$2:$D$49) -> 792375.56 | D8: =IFERROR(C8/B8,0) -> 1.007695 | E8: =C8-B8 -> 6050.7692 | F8: =SUMIF('Monthly Data'!$A$2:$A$49,$A8,'Monthly Data'!$G$2:$G$49) -> 419825.68 | G8: =SUMIF('Monthly Data'!$A$2:$A$49,$A8,'Monthly Data'!$H$2:$H$49) -> 372549.87 | H8: =IFERROR(G8/C8,0) -> 0.4701683 | I8: =SUMIF('Monthly Data'!$A$2:$A$49,$A8,'Monthly Data'!$K$2:$K$49) -> 657538.35 | J8: =SUMIF('Monthly Data'!$A$2:$A$49,$A8,'Monthly Data'!$L$2:$L$49) -> 969516.64 | K8: =IFERROR((J8/I8)*AVERAGEIF('Monthly Data'!$A$2:$A$49,$A8,'Monthly Data'!$M$2:$M$49),0) -> 44.233921 | L8: =SUMIF('Monthly Data'!$A$2:$A$49,$A8,'Monthly Data'!$O$2:$O$49) -> 634948.52 | M8: =IFERROR((F8*12)/L8,0) -> 7.934357
A9: May-2026 | B9: =SUMIF('Monthly Data'!$A$2:$A$49,$A9,'Monthly Data'!$C$2:$C$49) -> 769230.77 | C9: =SUMIF('Monthly Data'!$A$2:$A$49,$A9,'Monthly Data'!$D$2:$D$49) -> 772007.69 | D9: =IFERROR(C9/B9,0) -> 1.00361 | E9: =C9-B9 -> 2776.9231 | F9: =SUMIF('Monthly Data'!$A$2:$A$49,$A9,'Monthly Data'!$G$2:$G$49) -> 405582.5 | G9: =SUMIF('Monthly Data'!$A$2:$A$49,$A9,'Monthly Data'!$H$2:$H$49) -> 366425.19 | H9: =IFERROR(G9/C9,0) -> 0.4746393 | I9: =SUMIF('Monthly Data'!$A$2:$A$49,$A9,'Monthly Data'!$K$2:$K$49) -> 637184.81 | J9: =SUMIF('Monthly Data'!$A$2:$A$49,$A9,'Monthly Data'!$L$2:$L$49) -> 842108.98 | K9: =IFERROR((J9/I9)*AVERAGEIF('Monthly Data'!$A$2:$A$49,$A9,'Monthly Data'!$M$2:$M$49),0) -> 40.96987 | L9: =SUMIF('Monthly Data'!$A$2:$A$49,$A9,'Monthly Data'!$O$2:$O$49) -> 636621.94 | M9: =IFERROR((F9*12)/L9,0) -> 7.645024
A10: Jun-2026 | B10: =SUMIF('Monthly Data'!$A$2:$A$49,$A10,'Monthly Data'!$C$2:$C$49) -> 683760.68 | C10: =SUMIF('Monthly Data'!$A$2:$A$49,$A10,'Monthly Data'!$D$2:$D$49) -> 701278.63 | D10: =IFERROR(C10/B10,0) -> 1.02562 | E10: =C10-B10 -> 17517.949 | F10: =SUMIF('Monthly Data'!$A$2:$A$49,$A10,'Monthly Data'!$G$2:$G$49) -> 371945.3 | G10: =SUMIF('Monthly Data'!$A$2:$A$49,$A10,'Monthly Data'!$H$2:$H$49) -> 329333.33 | H10: =IFERROR(G10/C10,0) -> 0.46961838 | I10: =SUMIF('Monthly Data'!$A$2:$A$49,$A10,'Monthly Data'!$K$2:$K$49) -> 582328.89 | J10: =SUMIF('Monthly Data'!$A$2:$A$49,$A10,'Monthly Data'!$L$2:$L$49) -> 871708.7 | K10: =IFERROR((J10/I10)*AVERAGEIF('Monthly Data'!$A$2:$A$49,$A10,'Monthly Data'!$M$2:$M$49),0) -> 44.90806 | L10: =SUMIF('Monthly Data'!$A$2:$A$49,$A10,'Monthly Data'!$O$2:$O$49) -> 604679.44 | M10: =IFERROR((F10*12)/L10,0) -> 7.3813384
A11: Jul-2026 | B11: =SUMIF('Monthly Data'!$A$2:$A$49,$A11,'Monthly Data'!$C$2:$C$49) -> 641025.64 | C11: =SUMIF('Monthly Data'!$A$2:$A$49,$A11,'Monthly Data'!$D$2:$D$49) -> 641916.67 | D11: =IFERROR(C11/B11,0) -> 1.00139 | E11: =C11-B11 -> 891.02564 | F11: =SUMIF('Monthly Data'!$A$2:$A$49,$A11,'Monthly Data'!$G$2:$G$49) -> 339449.84 | G11: =SUMIF('Monthly Data'!$A$2:$A$49,$A11,'Monthly Data'!$H$2:$H$49) -> 302466.83 | H11: =IFERROR(G11/C11,0) -> 0.47119329 | I11: =SUMIF('Monthly Data'!$A$2:$A$49,$A11,'Monthly Data'!$K$2:$K$49) -> 532024.84 | J11: =SUMIF('Monthly Data'!$A$2:$A$49,$A11,'Monthly Data'!$L$2:$L$49) -> 759752.3 | K11: =IFERROR((J11/I11)*AVERAGEIF('Monthly Data'!$A$2:$A$49,$A11,'Monthly Data'!$M$2:$M$49),0) -> 44.269214 | L11: =SUMIF('Monthly Data'!$A$2:$A$49,$A11,'Monthly Data'!$O$2:$O$49) -> 538301.79 | M11: =IFERROR((F11*12)/L11,0) -> 7.5671271
A12: Aug-2026 | B12: =SUMIF('Monthly Data'!$A$2:$A$49,$A12,'Monthly Data'!$C$2:$C$49) -> 683760.68 | C12: =SUMIF('Monthly Data'!$A$2:$A$49,$A12,'Monthly Data'!$D$2:$D$49) -> 665528.21 | D12: =IFERROR(C12/B12,0) -> 0.973335 | E12: =C12-B12 -> -18232.479 | F12: =SUMIF('Monthly Data'!$A$2:$A$49,$A12,'Monthly Data'!$G$2:$G$49) -> 352214.87 | G12: =SUMIF('Monthly Data'!$A$2:$A$49,$A12,'Monthly Data'!$H$2:$H$49) -> 313313.33 | H12: =IFERROR(G12/C12,0) -> 0.47077394 | I12: =SUMIF('Monthly Data'!$A$2:$A$49,$A12,'Monthly Data'!$K$2:$K$49) -> 551873.33 | J12: =SUMIF('Monthly Data'!$A$2:$A$49,$A12,'Monthly Data'!$L$2:$L$49) -> 703733.87 | K12: =IFERROR((J12/I12)*AVERAGEIF('Monthly Data'!$A$2:$A$49,$A12,'Monthly Data'!$M$2:$M$49),0) -> 39.530357 | L12: =SUMIF('Monthly Data'!$A$2:$A$49,$A12,'Monthly Data'!$O$2:$O$49) -> 547161.11 | M12: =IFERROR((F12*12)/L12,0) -> 7.7245594
A13: Sep-2026 | B13: =SUMIF('Monthly Data'!$A$2:$A$49,$A13,'Monthly Data'!$C$2:$C$49) -> 897435.9 | C13: =SUMIF('Monthly Data'!$A$2:$A$49,$A13,'Monthly Data'!$D$2:$D$49) -> 955715.38 | D13: =IFERROR(C13/B13,0) -> 1.06494 | E13: =C13-B13 -> 58279.487 | F13: =SUMIF('Monthly Data'!$A$2:$A$49,$A13,'Monthly Data'!$G$2:$G$49) -> 505025.77 | G13: =SUMIF('Monthly Data'!$A$2:$A$49,$A13,'Monthly Data'!$H$2:$H$49) -> 450689.62 | H13: =IFERROR(G13/C13,0) -> 0.47157305 | I13: =SUMIF('Monthly Data'!$A$2:$A$49,$A13,'Monthly Data'!$K$2:$K$49) -> 791740.38 | J13: =SUMIF('Monthly Data'!$A$2:$A$49,$A13,'Monthly Data'!$L$2:$L$49) -> 1071361.7 | K13: =IFERROR((J13/I13)*AVERAGEIF('Monthly Data'!$A$2:$A$49,$A13,'Monthly Data'!$M$2:$M$49),0) -> 40.595191 | L13: =SUMIF('Monthly Data'!$A$2:$A$49,$A13,'Monthly Data'!$O$2:$O$49) -> 830156.22 | M13: =IFERROR((F13*12)/L13,0) -> 7.3002034
A14: Oct-2026 | B14: =SUMIF('Monthly Data'!$A$2:$A$49,$A14,'Monthly Data'!$C$2:$C$49) -> 982905.98 | C14: =SUMIF('Monthly Data'!$A$2:$A$49,$A14,'Monthly Data'!$D$2:$D$49) -> 983505.56 | D14: =IFERROR(C14/B14,0) -> 1.00061 | E14: =C14-B14 -> 599.57265 | F14: =SUMIF('Monthly Data'!$A$2:$A$49,$A14,'Monthly Data'!$G$2:$G$49) -> 515194.59 | G14: =SUMIF('Monthly Data'!$A$2:$A$49,$A14,'Monthly Data'!$H$2:$H$49) -> 468310.96 | H14: =IFERROR(G14/C14,0) -> 0.47616504 | I14: =SUMIF('Monthly Data'!$A$2:$A$49,$A14,'Monthly Data'!$K$2:$K$49) -> 810246.26 | J14: =SUMIF('Monthly Data'!$A$2:$A$49,$A14,'Monthly Data'!$L$2:$L$49) -> 1202497 | K14: =IFERROR((J14/I14)*AVERAGEIF('Monthly Data'!$A$2:$A$49,$A14,'Monthly Data'!$M$2:$M$49),0) -> 46.007503 | L14: =SUMIF('Monthly Data'!$A$2:$A$49,$A14,'Monthly Data'!$O$2:$O$49) -> 778342.6 | M14: =IFERROR((F14*12)/L14,0) -> 7.9429484
A15: Nov-2026 | B15: =SUMIF('Monthly Data'!$A$2:$A$49,$A15,'Monthly Data'!$C$2:$C$49) -> 1068376.1 | C15: =SUMIF('Monthly Data'!$A$2:$A$49,$A15,'Monthly Data'!$D$2:$D$49) -> 1076410.3 | D15: =IFERROR(C15/B15,0) -> 1.00752 | E15: =C15-B15 -> 8034.188 | F15: =SUMIF('Monthly Data'!$A$2:$A$49,$A15,'Monthly Data'!$G$2:$G$49) -> 570311.7 | G15: =SUMIF('Monthly Data'!$A$2:$A$49,$A15,'Monthly Data'!$H$2:$H$49) -> 506098.56 | H15: =IFERROR(G15/C15,0) -> 0.47017255 | I15: =SUMIF('Monthly Data'!$A$2:$A$49,$A15,'Monthly Data'!$K$2:$K$49) -> 893234.78 | J15: =SUMIF('Monthly Data'!$A$2:$A$49,$A15,'Monthly Data'!$L$2:$L$49) -> 1237529.8 | K15: =IFERROR((J15/I15)*AVERAGEIF('Monthly Data'!$A$2:$A$49,$A15,'Monthly Data'!$M$2:$M$49),0) -> 41.563421 | L15: =SUMIF('Monthly Data'!$A$2:$A$49,$A15,'Monthly Data'!$O$2:$O$49) -> 888175.66 | M15: =IFERROR((F15*12)/L15,0) -> 7.7053906
A16: Dec-2026 | B16: =SUMIF('Monthly Data'!$A$2:$A$49,$A16,'Monthly Data'!$C$2:$C$49) -> 1153846.2 | C16: =SUMIF('Monthly Data'!$A$2:$A$49,$A16,'Monthly Data'!$D$2:$D$49) -> 1192996.2 | D16: =IFERROR(C16/B16,0) -> 1.03393 | E16: =C16-B16 -> 39150 | F16: =SUMIF('Monthly Data'!$A$2:$A$49,$A16,'Monthly Data'!$G$2:$G$49) -> 627812.6 | G16: =SUMIF('Monthly Data'!$A$2:$A$49,$A16,'Monthly Data'!$H$2:$H$49) -> 565183.56 | H16: =IFERROR(G16/C16,0) -> 0.47375137 | I16: =SUMIF('Monthly Data'!$A$2:$A$49,$A16,'Monthly Data'!$K$2:$K$49) -> 985711.44 | J16: =SUMIF('Monthly Data'!$A$2:$A$49,$A16,'Monthly Data'!$L$2:$L$49) -> 1350128.8 | K16: =IFERROR((J16/I16)*AVERAGEIF('Monthly Data'!$A$2:$A$49,$A16,'Monthly Data'!$M$2:$M$49),0) -> 42.460695 | L16: =SUMIF('Monthly Data'!$A$2:$A$49,$A16,'Monthly Data'!$O$2:$O$49) -> 968904.24 | M16: =IFERROR((F16*12)/L16,0) -> 7.7755374
A17: Full Year | B17: =SUM(B5:B16) -> 10000000 | C17: =SUM(C5:C16) -> 10129013 | D17: =IFERROR(C17/B17,0) -> 1.0129013 | E17: =C17-B17 -> 129013.12 | F17: =SUM(F5:F16) -> 5339309.8 | G17: =SUM(G5:G16) -> 4789703.3 | H17: =IFERROR(G17/C17,0) -> 0.47286969 | I17: =SUM(I5:I16) -> 8378013.7 | J17: =AVERAGE(J5:J16) -> 973123.64 | K17: =AVERAGE(K5:K16) -> 42.370671 | L17: =AVERAGE(L5:L16) -> 692977.57 | M17: =AVERAGE(M5:M16) -> 7.7039104

Sheet Business Unit Analysis
A1: Business Unit Analysis
A2: Full-year performance by business unit — aggregated live from Monthly Data.
A4: Business Unit | B4: Revenue Target (AED) | C4: Revenue Actual (AED) | D4: Achievement % | E4: Gross Margin % | F4: Avg DSO (Days) | G4: Avg Inventory Turnover (x)
A5: Executive & Corporate Services | B5: =SUMIF('Monthly Data'!$B$2:$B$49,$A5,'Monthly Data'!$C$2:$C$49) -> 3500000 | C5: =SUMIF('Monthly Data'!$B$2:$B$49,$A5,'Monthly Data'!$D$2:$D$49) -> 3617928.5 | D5: =IFERROR(C5/B5,0) -> 1.0336938 | E5: =IFERROR(SUMIF('Monthly Data'!$B$2:$B$49,$A5,'Monthly Data'!$H$2:$H$49)/C5,0) -> 0.45 | F5: =AVERAGEIF('Monthly Data'!$B$2:$B$49,$A5,'Monthly Data'!$N$2:$N$49) -> 44.647875 | G5: =AVERAGEIF('Monthly Data'!$B$2:$B$49,$A5,'Monthly Data'!$P$2:$P$49) -> 7.8600882
A6: Client Operations & Revenue Recovery | B6: =SUMIF('Monthly Data'!$B$2:$B$49,$A6,'Monthly Data'!$C$2:$C$49) -> 3000000 | C6: =SUMIF('Monthly Data'!$B$2:$B$49,$A6,'Monthly Data'!$D$2:$D$49) -> 2962190.3 | D6: =IFERROR(C6/B6,0) -> 0.98739675 | E6: =IFERROR(SUMIF('Monthly Data'!$B$2:$B$49,$A6,'Monthly Data'!$H$2:$H$49)/C6,0) -> 0.4 | F6: =AVERAGEIF('Monthly Data'!$B$2:$B$49,$A6,'Monthly Data'!$N$2:$N$49) -> 49.007917 | G6: =AVERAGEIF('Monthly Data'!$B$2:$B$49,$A6,'Monthly Data'!$P$2:$P$49) -> 6.014932
A7: Product & Technology (Atrium) | B7: =SUMIF('Monthly Data'!$B$2:$B$49,$A7,'Monthly Data'!$C$2:$C$49) -> 2000000 | C7: =SUMIF('Monthly Data'!$B$2:$B$49,$A7,'Monthly Data'!$D$2:$D$49) -> 2023122.2 | D7: =IFERROR(C7/B7,0) -> 1.0115611 | E7: =IFERROR(SUMIF('Monthly Data'!$B$2:$B$49,$A7,'Monthly Data'!$H$2:$H$49)/C7,0) -> 0.6 | F7: =AVERAGEIF('Monthly Data'!$B$2:$B$49,$A7,'Monthly Data'!$N$2:$N$49) -> 29.31925 | G7: =AVERAGEIF('Monthly Data'!$B$2:$B$49,$A7,'Monthly Data'!$P$2:$P$49) -> 12.13896
A8: Consulting & Advisory | B8: =SUMIF('Monthly Data'!$B$2:$B$49,$A8,'Monthly Data'!$C$2:$C$49) -> 1500000 | C8: =SUMIF('Monthly Data'!$B$2:$B$49,$A8,'Monthly Data'!$D$2:$D$49) -> 1525772.2 | D8: =IFERROR(C8/B8,0) -> 1.0171815 | E8: =IFERROR(SUMIF('Monthly Data'!$B$2:$B$49,$A8,'Monthly Data'!$H$2:$H$49)/C8,0) -> 0.5 | F8: =AVERAGEIF('Monthly Data'!$B$2:$B$49,$A8,'Monthly Data'!$N$2:$N$49) -> 37.354667 | G8: =AVERAGEIF('Monthly Data'!$B$2:$B$49,$A8,'Monthly Data'!$P$2:$P$49) -> 10.12666
A9: Total / Average | B9: =SUM(B5:B8) -> 10000000 | C9: =SUM(C5:C8) -> 10129013 | D9: =IFERROR(C9/B9,0) -> 1.0129013 | E9: =AVERAGE(E5:E8) -> 0.4875 | F9: =AVERAGE(F5:F8) -> 40.082427 | G9: =AVERAGE(G5:G8) -> 9.0351601

Sheet Executive Dashboard
B2: Executive Dashboard
B3: AED 10,000,000 Annual Business Value | FY2026 | All figures live from Monthly Data
B5: ANNUAL REVENUE TARGET | D5: ANNUAL REVENUE ACTUAL | G5: ACHIEVEMENT | I5: GROSS MARGIN
B6: ='KPI Tracker'!$B$17 -> 10000000 | D6: ='KPI Tracker'!$C$17 -> 10129013 | G6: ='KPI Tracker'!$D$17 -> 1.0129013 | I6: ='KPI Tracker'!$H$17 -> 0.47286969
B8: FY2026 full-year target | D8: FY2026 full-year actual | G8: Actual vs target | I8: Full-year average
B10: AVERAGE DSO | D10: INVENTORY TURNOVER | G10: TOTAL RECEIVABLES | I10: REVENUE VARIANCE
B11: ='KPI Tracker'!$K$17 -> 42.370671 | D11: ='KPI Tracker'!$M$17 -> 7.7039104 | G11: ='KPI Tracker'!$J$17 -> 973123.64 | I11: ='KPI Tracker'!$E$17 -> 129013.12
B13: Days sales outstanding | D13: Annualized, average | G13: Average monthly closing balance | I13: Actual less target, FY2026
B52: Source: Monthly Data (fact table) -> KPI Tracker / Business Unit Analysis (aggregation) -> Executive Dashboard (presentation). No values are typed directly on this tab.
